Workbook

Sheet 版本说明
D7: 版本 | E7: 修改时间 | F7: 修改人 | G7: 备注
D8: 1 | E8: 45139 | F8: xy | G8: 贴吧首发地址：https://tieba.baidu.com/p/8530450428
D9: 1.1 | E9: 45149 | F9: xy | G9: 1. 更新了相对更加准确的英雄舞阳老四、老五、老六的属性测试值（主要是格挡）。 2. 增加了克制百分比的计算功能，并更新了相应的计算公式。 3. 属性变化计算器中，增加了力量/气海和身法属性的计算功能。 4. 追加了命中和会心的伤害提升百分比图。
D10: 1.2 | E10: 45253 | F10: kkxp | G10: 1. 更新了1.2木桩的参考数据，误差非常小 2. 将技能系数更换为龙吟斩霜一段 3. 现在破盾考虑目标的气盾情况，根据大多数人的破盾情况，只考虑破盾大于对方气盾1/3,且小于对面气盾的情况。
D11: 1.3 | E11: 45267 | F11: kkxp | G11: 1. 更新了普通镜天阁的boss属性（稍微有误差，不影响计算） 2. 在属性变化计算器中，增加了龙吟特质根骨对破防的转换
D12: 2.1 | E12: 45492 | F12: 折字为安 | G12: 1.全面更新79版本公式（元素自测，元素公式和团本有差异，可能需修改） 2.命中和会心公式通过游戏内面板计算得到，符合77天机团本，命中公式经过PVP实测 3.这里的命中公式直接用了阿娟的，其他公式均由本人计算拟合 4.增加了5%底层会心率判定，让情况更贴合实际 5.BOSS没有气盾，为了贴合当前版本PVP，剩余气盾默认大于三倍破盾 6.时间原因，没有在下方的面板中加入忽视元抗，具体按第一个来计算
D18: 2.1.1 | E18: 45493 | F18: 折字为安 | G18: 修正两个未改的破防系数，一个命中系数，增加常驻减伤百分比，增加内功词条收益
D19: 2.1.2 | E19: 45493 | F19: 折字为安 | G19: 修正后面表格命中的命中会心公式并补正收益率，将技能系数改为蓄满的凛月如勾
D20: 2.1.3 | E20: 45493 | F20: 折字为安 | G20: 1:根据群友iyun的建议给两个属性对比表加入了忽视元抗模块 2::优化忽视元素超过元抗,破防超过防御时的计算逻辑
D22: 2.1.4 | E22: 45498 | F22: 折字为安 | G22: 1增加元素伤害占比模块，优化计算器排版，属性变化计算器增加忽视元素模块 2：增加三金会心伤害方便估算最高极限伤害 3：增加纯PVE版本，修改相应系数为2.1团本木桩
D25: 2.1.5 | E25: 45499 | F25: 折字为安 | G25: 下面四个过程量中的剩余气盾公式没改，现已修正
D26: 2.1.6 | E26: 45507 | F26: 折字为安 | G26: 修正79级PVP系数，让误差在0.2%以内，修改参考属性，系数增加玄机普攻一段参考
D27: 2.1.7 | E27: 45513 | F27: 折字为安 | G27: 修改倍率为100%，受击方增加血量和血量/伤害期望，即能抗多少倍率的伤害
D28: 2.1.8 | E28: 45533 | F28: 折字为安 | G28: 增加技能抵御，增强，会心防御，并将技能基础加入元素占比中，使之更贴合实际
D29: 2.1.9 | E29: 45555 | F29: 折字为安 | G29: 增加萃锋镝等效提升以及保底伤害，增加全职业参考系数，修改技能基础为35级
D30: 2.2.1 | E30: 45591 | F30: 折字为安 | G30: 全面更新公式修改自测各个PVP系数（待修正），加入技巧克制，更新版本词条数值
D31: 2.2.2 | E31: 45593 | F31: 折字为安 | G31: 修正表格中破防满之后收益问题，对比器会心率问题，加入技巧克制，气盾灵活判定
D32: 2.2.3 | E32: 45610 | F32: 折字为安 | G32: 随技能升级增加技能系数1（40级左右），修正属性收益估算表上未修改部分
... D36: 2.2.7 | E36: 45696 | F36: 折字为安 | G36: 修复一个文字描述，加入技能增强百分比模块，更新内功满词条数据及收益 加入部分区域保护，防止修改到不需要填的部分

Sheet 属性输入
B1: 说明： | N1: 注意，实际能吃百分比的词条，如攻击等收益吃剑心和破釜会放大
B2: 1、灰底红字的部分可以修改（除了推荐属性的部分以外），其他部分请不要修改！ | N2: 393破防 | O2: ='破防提升收益'!AA4 -> 0.014519781
B3: 2、计算过程包含部分估算的参数，结果会有误差，但不会很大。拉到底部可查看计算器使用的公式。 | N3: 269攻击 | O3: ='攻击提升收益'!T4 -> 0.0091904417
B4: 3、计算器结果可能随游戏版本更新而失效。 | N4: 159元素 | O4: ='元素攻击提升收益'!S4 -> 0.0057218785
B5: 4、现在破盾考虑目标的气盾情况，计算器会自行判定，但是破盾收益按两倍克制算 | N5: 209破盾 | O5: ='攻击提升收益'!T5 -> 0.014281058 | P5: 破盾只考虑小于对方三倍气盾时，如大于，收益逐渐降低，直到1比1攻击
B6: 5：因为折某本人精力有限，计算器的优化需要群力群为，本计算器完全开源，有优化的交流和建议联系B站折字愿为安 | N6: 137会心 | O6: ='会心提升收益'!V4 -> 0.0096270345
B7: 6：元素额外乘区仅输入新特质和萃锋即可，技巧克制对攻击方规则为低打高双方技巧克制无效，高打低多的为克制 | N7: 116命中 | O7: ='命中提升收益'!U4 -> 0
B8: 下方输入受到攻击的敌人的属性，可参考推荐属性。这里采用的是大众面板，可自行修改 | R8: 昆吾等效 | S8: 14.2%会伤（灵韵19.2%）
B9: 受击方面板属性 | R9: 明佑等效 | S9: 286克制+357破防+238元素
B10: 防御 | C10: 气盾 | D10: 元素抗性 | E10: 抵御 | F10: 格挡 | G10: 会心抵抗 | H10: 抵御百分比 | I10: 血量 | J10: 会心防御 | K10: 技能抵御 | L10: 技能减免百分比 | M10: 技巧克制 | N10: 血量/伤害期望 | O10: 减伤百分比（日月区） | R10: 撩野等效 | S10: 0.0433
B11: 18500 | C11: 4000 | D11: 4500 | E11: 7000 | F11: 3500 | G11: 2600 | H11: 0.32 | I11: 490000 | J11: 0.25 | K11: 0 | L11: 0 | M11: 5311 | N11: =I11/D27 -> 24.943548 | O11: 0.2
A12: 属性变化量 | I12: 0 | J12: 0 | L12: 0
A13: 变化后属性 | B13: =B11+B12 -> 18500 | C13: =C11+C12 -> 4000 | D13: =D11+D12 -> 4500 | E13: =E11+E12 -> 7000 | F13: =F11+F12 -> 3500 | G13: =G11+G12 -> 2600 | H13: =H11+H12 -> 0.32 | I13: =I11+I12 -> 490000 | J13: =J12+J11 -> 0.25 | K13: =K11+K12 -> 0 | L13: =L11+L12 -> 0 | M13: =M11+M12 -> 5311 | N13: =I13/D30 -> 24.943548 | O13: =O11+O12 -> 0.2
H14: 常驻减伤不包括日月等乘区，为流派抵御加打造 | O14: 注意攻击方的攻击增伤百分比和元素增伤百分比及防守方减伤百分比，同属日月区
B15: 防御 | C15: 气盾 | D15: 元素抗性 | E15: 抵御 | F15: 格挡 | G15: 会心抵抗 | H15: 常用倍率 | AE15: 193
A16: 防御塔属性 | B16: 1146 | C16: 0 | D16: 0 | E16: 0 | F16: 343 | G16: 250 | H16: 老橙戒200%+5*45%倍率 | J16: =MAX(I25-J11,50%) -> 0.687 | N16: 注意断金戈等是独立乘区，伤害可以直接乘1.12 | AE16: 250 | AF16: =AE16/AE15 -> 1.2953368
A17: 素问属性 | B17: 13000 | C17: 3500 | D17: 3000 | E17: 4700 | F17: 2200 | G17: 3000 | J17: =MAX(I25-J13,50%) -> 0.687 | N17: 系数为100%倍率，可自行修改 | AF17: =1.3*0.7+1*0.3 -> 1.21
A18: 龙玄属性 | B18: 11000 | C18: 1200 | D18: 2800 | E18: 3500 | F18: 2000 | G18: 2800 | N18: 系数1 | O18: 系数2 | R18: 技能等级
A19: 全独珍属性 | B19: 8000 | C19: 300 | D19: 2400 | E19: 2000 | F19: 1900 | G19: 2200 | N19: 3050 | O19: 1 | R19: 41
A20: 神九属性 | B20: 11000 | C20: 1200 | D20: 2500 | E20: 3500 | F20: 2100 | G20: 2700 | M20: 碎梦普攻一段系数为： | O20: 0.3123
A21: 天机迷城 | B21: 12020 | C21: 0 | D21: 2500 | E21: 13900 | F21: 2556 | G21: 2315 | N21: 满勾子系数 | O21: 6.05
B22: 在下方输入面板属性，可以计算目前各个属性的收益率（切换页签可查看收益率曲线）；也可以用属性变化计算器，计算各个属性变化一定量后伤害提升的百分比。
A23: 静态攻击方面板属性（默认带了破釜+剑心+刀意） | O23: 过程量 | W23: 目标面板 | X23: 防御系数 | Y23: 元抗系数 | Z23: 命中系数 | AA23: 会心系数
A24: 忽视元抗 | B24: 攻击 | C24: 破防 | D24: 破盾 | E24: 元素攻击 | F24: 克制数值 | G24: 命中 | H24: 会心 | I24: 会伤-100% | J24: 额外会心率 | K24: 克制百分比 | L24: 技能增强百分比 | M24: 元素伤害占比 | N24: 技能增强 | O24: 剩余防御 | P24: 防御减免 | Q24: 技能剩余百分比 | R24: 剩余气盾 | S24: 元素抗性减免
A25: 2100 | B25: 17500 | C25: 13000 | D25: 500 | E25: 6200 | F25: 11500 | G25: 4400 | H25: 4600 | I25: 0.937 | J25: 0 | K25: 0.193 | L25: 0 | M25: =((E25*$O$19*(1-S25))*(1+M27-O11)/((N19+($O$19*(B25-$E$11+F25+N25-K11-R25)))*(1-P25)*(1+K27-O11)+E25*$O$19*(1-S25)*(1+M27-O11))) -> 0.22849603 | N25: 0 | O25: =MAX($B$11-C25,0) -> 5500 | P25: =MAX(0.1+(O25/(O25+19032)),0.1) -> 0.32419697 | Q25: =1+(L25-L11) -> 1 | R25: =IF(C11/3>D25,C11-2*D25,0.5*(C11-D25)) -> 3000 | S25: =MAX((($D$11-A25)/($D$11-A25+4762)),0) -> 0.33510193 | T25: =D11-A25 -> 2400 | W25: 2.2版本 | X25: 19032 | Y25: 4763 | Z25: 10686 | AA25: 2666
A26: 三金会心 | B26: 未会心伤害 | D26: 包含命中会心的伤害期望 | K26: 攻击增伤比 | L26: 特殊乘区 | M26: 元素增伤百分比 | N26: 技巧克制 | O26: 实际命中率 | P26: 实际会心率 | Q26: 特殊乘区 | R26: =MAX(R25,0) -> 3000 | S26: 技巧克制差 | U26: =1-P25 -> 0.67580303 | W26: 2.3版本
A27: =(1+I25+1.5)*E42 -> 55493.411 | B27: =(($N$19+$O$19*(B25-$E$11+F25+N25-R26-K11+S27))*(1-P25)*(1+K27-O11)+(1+M27-O11)*E25*$O$19*(1-S25))*(1+K25-H11)*Q25 -> 14678.078 | D27: =B27*O27*(1+J16*P27)+0.5*B27*(1-O27) -> 19644.359 | F27: 要算出游戏内显示的伤害，需要再乘上各个技能的技能倍率以及各种增伤。 | K27: 0.05 | M27: 0.11 | N27: 6000 | O27: =MIN((143*(G25-F11)/(G25-F11+10688)+95)/100,1) -> 1 | P27: =MAX((((115*(H25-$G$11)-200)/((H25-$G$11)+2666)/100)),0.05)+J25 -> 0.49249893 | S27: =IF(N27>M11,N27-M11,0) -> 689
I28: 防御变化后 | J28: 剩余防御 | K28: 防御减免 | L28: 技能剩余百分比 | M28: 剩余气盾 | N28: 元素抗性减免
A29: 防御变化后 | B29: 未会心伤害 | D29: 包含命中会心的伤害期望 | F29: 肉度变化 | J29: =MAX(B13-C25,0) -> 5500 | K29: =MAX(0.1+(J29/(J29+19032)),0.1) -> 0.32419697 | L29: =1+(L25-L13) -> 1 | M29: =IF(C13/3>D25,C13-2*D25,0.5*(C13-D25)) -> 3000 | N29: =MAX(((D13-A25)/(D13-A25+4762)),0) -> 0.33510193
B30: =(($N$19+$O$19*(B25-E13+F25+N25-M30-K13+N31))*(1-K29)*(1+K27-O13)+(1+M27-O13)*E25*$O$19*(1-N29))*(1+K25-H13)*L29 -> 14678.078 | D30: =B30*J31*(1+J17*K31)+0.5*B30*(1-J31) -> 19644.359 | F30: =N13/N11-1 -> 0 | J30: 实际命中率 | K30: 实际会心率 | L30: 特殊乘区 | M30: =MAX(M29,0) -> 3000 | N30: 技巧克制差
B31: 属性收益估算（在上方面板情况下，提升一定量某属性，对应提升的伤害百分比） | H31: 会心伤害 | I31: 保底伤害(无格挡) | J31: =MIN((143*(G25-F13)/(G25-F13+10688)+95)/100,1) -> 1 | K31: =MAX((((115*(H25-G13)-200)/((H25-G13)+2666)/100)),0.05)+J25 -> 0.49249893 | N31: =IF(N27>M13,N27-M13,0) -> 689
B32: 攻击提升100点 | C32: 破防提升100点 | D32: 元素攻击提升50点 | E32: 命中提升21点 | F32: 会心提升25点 | H32: =B27*(1+J16) -> 24761.918 | I32: =0.15*(O19*(B25+E25)+N19) -> 4012.5 | O32: 50会心率剩余会心2100左右，55会心率2450左右
B33: ='攻击提升收益'!$F$2 -> 0.0034165211 | C33: ='破防提升收益'!Z2 -> 0.0036502935 | D33: ='元素攻击提升收益'!$E$2 -> 0.0017993329 | E33: ='命中提升收益'!$F$2 -> 0 | F33: ='会心提升收益'!$F$2 -> 0.001798587 | G33: 数值最高的是提升收益最大的，但是因为还有各种百分比加成等因素，仅用于粗略估计。 | O33: 真实会心率=命中率*实际会心率
B34: 攻击提升224点 | C34: 破防提升300点 | D34: 元素攻提升100点 | E34: 命中提升40点 | F34: 会心提升100点 | N34: 注意实战有火周天催锋等必定命中且不会心，乾坤金等必会心，会影响最后结算伤害会心率，以计算器结果为准
B35: ='攻击提升收益'!T4 -> 0.0091904417 | C35: ='破防提升收益'!E4 -> 0.011041264 | D35: ='元素攻击提升收益'!R2 -> 0.0035986657 | E35: ='命中提升收益'!$V$2 -> 0 | F35: ='会心提升收益'!U5 -> 0.0070815856 | G35: 这里则是按各个属性等价计算，作为参考。
A37: 属性变化计算器1（计算在上方攻击方面板的基础上，属性变化一定量后提升的伤害，变化量可为正可为负） | O37: 过程量
B38: 攻击 | C38: 破防 | D38: 破盾 | E38: 元素攻击 | F38: 克制数值 | G38: 命中 | H38: 会心 | I38: 会伤 | J38: 额外会心率 | K38: 克制百分比 | L38: 技能增强百分比 | M38: 忽视元抗 | N38: 技能增强 | O38: 剩余防御 | P38: 防御减免 | Q38: 技能剩余百分比 | R38: 剩余气盾 | S38: 元素抗性减免
A39: 属性变化量 | B39: 0 | D39: 0 | G39: 0 | H39: 4600 | I39: 0 | L39: 0.1 | O39: =MAX($B$11-C40,0) -> 5500 | P39: =MAX(0.1+(O39/(O39+19032)),0.1) -> 0.32419697 | Q39: =1+(L40-L11) -> 1.1 | R39: =IF(C11/3>D40,C11-2*D40,0.5*(C11-D40)) -> 3000 | S39: =MAX((($D$11-M40)/($D$11-M40+4762)),0) -> 0.33510193
A40: 变化后属性 | B40: =B$25+B39+ROUNDDOWN(B42*4.65,0) -> 17500 | C40: =C$25+C39+B42*2+ROUNDDOWN(D42*2,0) -> 13000 | D40: =D$25+D39 -> 500 | E40: =E$25+E39 -> 6200 | F40: =F$25+F39 -> 11500 | G40: =G$25+G39+ROUNDDOWN(C42*0.83,0) -> 4400 | H40: 0 | I40: =I$25+I39 -> 0.937 | J40: =J$25+J39 -> 0 | K40: =K$25+K39 -> 0.193 | L40: =L25+L39 -> 0.1 | M40: =A25+M39 -> 2100 | N40: =N25+N39 -> 0 | O40: 实际命中率 | P40: 实际会心率 | R40: =MAX(R39,0) -> 3000 | S40: 技巧克制差
B41: 力量/气海 | C41: 身法 | D41: 根骨 | E41: 未会心伤害 | G41: 包含命中会心的伤害期望 | I41: 伤害期望提升百分比 | K41: 攻击增伤比 | L41: 特殊乘区 | M41: 元素额外乘区 | N41: 技巧克制 | O41: =MIN((143*(G40-F11)/(G40-F11+10688)+95)/100,1) -> 1 | P41: =MAX((((115*(H40-$G$11)-200)/((H40-$G$11)+2666)/100)),0.05)+J40 -> 0.05 | S41: =IF(N42>M11,N42-M11,0) -> 689 | V41: 入梦之光 | W41: =IFS(B47="无",0,B47="悟",15+3*R19,B47="携",16+4*R19) -> 138
...

Sheet 攻击提升收益
A1: 攻击提升 | B1: 伤害 | C1: 伤害提升百分比 | D1: y=0.1 | E1: 攻击 | F1: 每增加100点攻击收益率 | P1: 攻击提升 | Q1: 伤害 | R1: 攻击 | S1: 每增加100点攻击收益率
A2: 0 | B2: =('属性输入'!$N$19+'属性输入'!$O$19*('属性输入'!$B$25+A2-'属性输入'!$E$11+'属性输入'!$F$25-'属性输入'!$R$25+'属性输入'!$N$25-'属性输入'!$K$11+'属性输入'!$S$27))*(1-'属性输入'!$P$25)*(1+'属性输入'!$K$27-'属性输入'!$O$11)+(1+'属性输入'!$M$27-'属性输入'!$O$11)*'属性输入'!$O$19*(1-'属性输入'!$S$25)*'属性输入'!$E$25 -> 16813.377 | C2: =(B2-$B$2)/$B$2 -> 0 | D2: 0.1 | E2: ='属性输入'!$B$25 -> 17500 | F2: =(B3-B2)/B2 -> 0.0034165211 | P2: 0 | Q2: =('属性输入'!$N$19+'属性输入'!$O$19*('属性输入'!$B$25+P2-'属性输入'!$E$11+'属性输入'!$F$25-'属性输入'!$R$25+'属性输入'!$N$25-'属性输入'!$K$11+'属性输入'!$S$27))*(1-'属性输入'!$P$25)*(1+'属性输入'!$K$27-'属性输入'!$O$11)+(1+'属性输入'!$M$27-'属性输入'!$O$11)*'属性输入'!$O$19*(1-'属性输入'!$S$25)*'属性输入'!$E$25 -> 16813.377 | R2: ='属性输入'!$B$25 -> 17500 | S2: =(Q3-Q2)/Q2 -> 0.0034165211 | T2: 224攻击收益率
A3: 100 | B3: =('属性输入'!$N$19+'属性输入'!$O$19*('属性输入'!$B$25+A3-'属性输入'!$E$11+'属性输入'!$F$25-'属性输入'!$R$25+'属性输入'!$N$25-'属性输入'!$K$11+'属性输入'!$S$27))*(1-'属性输入'!$P$25)*(1+'属性输入'!$K$27-'属性输入'!$O$11)+(1+'属性输入'!$M$27-'属性输入'!$O$11)*'属性输入'!$O$19*(1-'属性输入'!$S$25)*'属性输入'!$E$25 -> 16870.821 | C3: =(B3-$B$2)/$B$2 -> 0.0034165211 | D3: 0.1 | E3: =$E$2+A3 -> 17600 | F3: =(B4-B3)/B3 -> 0.0034048882 | P3: 100 | Q3: =('属性输入'!$N$19+'属性输入'!$O$19*('属性输入'!$B$25+P3-'属性输入'!$E$11+'属性输入'!$F$25-'属性输入'!$R$25+'属性输入'!$N$25-'属性输入'!$K$11+'属性输入'!$S$27))*(1-'属性输入'!$P$25)*(1+'属性输入'!$K$27-'属性输入'!$O$11)+(1+'属性输入'!$M$27-'属性输入'!$O$11)*'属性输入'!$O$19*(1-'属性输入'!$S$25)*'属性输入'!$E$25 -> 16870.821 | R3: =$E$2+P3 -> 17600
A4: 200 | B4: =('属性输入'!$N$19+'属性输入'!$O$19*('属性输入'!$B$25+A4-'属性输入'!$E$11+'属性输入'!$F$25-'属性输入'!$R$25+'属性输入'!$N$25-'属性输入'!$K$11+'属性输入'!$S$27))*(1-'属性输入'!$P$25)*(1+'属性输入'!$K$27-'属性输入'!$O$11)+(1+'属性输入'!$M$27-'属性输入'!$O$11)*'属性输入'!$O$19*(1-'属性输入'!$S$25)*'属性输入'!$E$25 -> 16928.264 | C4: =(B4-$B$2)/$B$2 -> 0.0068330421 | D4: 0.1 | E4: =$E$2+A4 -> 17700 | F4: =(B5-B4)/B4 -> 0.0033933343 | P4: 269 | Q4: =('属性输入'!$N$19+'属性输入'!$O$19*('属性输入'!$B$25+P4-'属性输入'!$E$11+'属性输入'!$F$25-'属性输入'!$R$25+'属性输入'!$N$25-'属性输入'!$K$11+'属性输入'!$S$27))*(1-'属性输入'!$P$25)*(1+'属性输入'!$K$27-'属性输入'!$O$11)+(1+'属性输入'!$M$27-'属性输入'!$O$11)*'属性输入'!$O$19*(1-'属性输入'!$S$25)*'属性输入'!$E$25 -> 16967.9 | R4: =R2+P4 -> 17769 | T4: =(Q4-Q2)/Q2 -> 0.0091904417
A5: 300 | B5: =('属性输入'!$N$19+'属性输入'!$O$19*('属性输入'!$B$25+A5-'属性输入'!$E$11+'属性输入'!$F$25-'属性输入'!$R$25+'属性输入'!$N$25-'属性输入'!$K$11+'属性输入'!$S$27))*(1-'属性输入'!$P$25)*(1+'属性输入'!$K$27-'属性输入'!$O$11)+(1+'属性输入'!$M$27-'属性输入'!$O$11)*'属性输入'!$O$19*(1-'属性输入'!$S$25)*'属性输入'!$E$25 -> 16985.707 | C5: =(B5-$B$2)/$B$2 -> 0.010249563 | D5: 0.1 | E5: =$E$2+A5 -> 17800 | F5: =(B6-B5)/B5 -> 0.0033818585 | P5: 418 | Q5: =('属性输入'!$N$19+'属性输入'!$O$19*('属性输入'!$B$25+P5-'属性输入'!$E$11+'属性输入'!$F$25-'属性输入'!$R$25+'属性输入'!$N$25-'属性输入'!$K$11+'属性输入'!$S$27))*(1-'属性输入'!$P$25)*(1+'属性输入'!$K$27-'属性输入'!$O$11)+(1+'属性输入'!$M$27-'属性输入'!$O$11)*'属性输入'!$O$19*(1-'属性输入'!$S$25)*'属性输入'!$E$25 -> 17053.49 | R5: =R2+P5 -> 17918 | T5: =(Q5-Q2)/Q2 -> 0.014281058
A6: 400 | B6: =('属性输入'!$N$19+'属性输入'!$O$19*('属性输入'!$B$25+A6-'属性输入'!$E$11+'属性输入'!$F$25-'属性输入'!$R$25+'属性输入'!$N$25-'属性输入'!$K$11+'属性输入'!$S$27))*(1-'属性输入'!$P$25)*(1+'属性输入'!$K$27-'属性输入'!$O$11)+(1+'属性输入'!$M$27-'属性输入'!$O$11)*'属性输入'!$O$19*(1-'属性输入'!$S$25)*'属性输入'!$E$25 -> 17043.15 | C6: =(B6-$B$2)/$B$2 -> 0.013666084 | D6: 0.1 | E6: =$E$2+A6 -> 17900 | F6: =(B7-B6)/B6 -> 0.0033704601
A7: 500 | B7: =('属性输入'!$N$19+'属性输入'!$O$19*('属性输入'!$B$25+A7-'属性输入'!$E$11+'属性输入'!$F$25-'属性输入'!$R$25+'属性输入'!$N$25-'属性输入'!$K$11+'属性输入'!$S$27))*(1-'属性输入'!$P$25)*(1+'属性输入'!$K$27-'属性输入'!$O$11)+(1+'属性输入'!$M$27-'属性输入'!$O$11)*'属性输入'!$O$19*(1-'属性输入'!$S$25)*'属性输入'!$E$25 -> 17100.594 | C7: =(B7-$B$2)/$B$2 -> 0.017082605 | D7: 0.1 | E7: =$E$2+A7 -> 18000 | F7: =(B8-B7)/B7 -> 0.0033591382
A8: 600 | B8: =('属性输入'!$N$19+'属性输入'!$O$19*('属性输入'!$B$25+A8-'属性输入'!$E$11+'属性输入'!$F$25-'属性输入'!$R$25+'属性输入'!$N$25-'属性输入'!$K$11+'属性输入'!$S$27))*(1-'属性输入'!$P$25)*(1+'属性输入'!$K$27-'属性输入'!$O$11)+(1+'属性输入'!$M$27-'属性输入'!$O$11)*'属性输入'!$O$19*(1-'属性输入'!$S$25)*'属性输入'!$E$25 -> 17158.037 | C8: =(B8-$B$2)/$B$2 -> 0.020499126 | D8: 0.1 | E8: =$E$2+A8 -> 18100 | F8: =(B9-B8)/B8 -> 0.0033478922
A9: 700 | B9: =('属性输入'!$N$19+'属性输入'!$O$19*('属性输入'!$B$25+A9-'属性输入'!$E$11+'属性输入'!$F$25-'属性输入'!$R$25+'属性输入'!$N$25-'属性输入'!$K$11+'属性输入'!$S$27))*(1-'属性输入'!$P$25)*(1+'属性输入'!$K$27-'属性输入'!$O$11)+(1+'属性输入'!$M$27-'属性输入'!$O$11)*'属性输入'!$O$19*(1-'属性输入'!$S$25)*'属性输入'!$E$25 -> 17215.48 | C9: =(B9-$B$2)/$B$2 -> 0.023915647 | D9: 0.1 | E9: =$E$2+A9 -> 18200 | F9: =(B10-B9)/B9 -> 0.0033367212 | U9: 0.08
A10: 800 | B10: =('属性输入'!$N$19+'属性输入'!$O$19*('属性输入'!$B$25+A10-'属性输入'!$E$11+'属性输入'!$F$25-'属性输入'!$R$25+'属性输入'!$N$25-'属性输入'!$K$11+'属性输入'!$S$27))*(1-'属性输入'!$P$25)*(1+'属性输入'!$K$27-'属性输入'!$O$11)+(1+'属性输入'!$M$27-'属性输入'!$O$11)*'属性输入'!$O$19*(1-'属性输入'!$S$25)*'属性输入'!$E$25 -> 17272.923 | C10: =(B10-$B$2)/$B$2 -> 0.027332169 | D10: 0.1 | E10: =$E$2+A10 -> 18300 | F10: =(B11-B10)/B10 -> 0.0033256245
A11: 900 | B11: =('属性输入'!$N$19+'属性输入'!$O$19*('属性输入'!$B$25+A11-'属性输入'!$E$11+'属性输入'!$F$25-'属性输入'!$R$25+'属性输入'!$N$25-'属性输入'!$K$11+'属性输入'!$S$27))*(1-'属性输入'!$P$25)*(1+'属性输入'!$K$27-'属性输入'!$O$11)+(1+'属性输入'!$M$27-'属性输入'!$O$11)*'属性输入'!$O$19*(1-'属性输入'!$S$25)*'属性输入'!$E$25 -> 17330.367 | C11: =(B11-$B$2)/$B$2 -> 0.03074869 | D11: 0.1 | E11: =$E$2+A11 -> 18400 | F11: =(B12-B11)/B11 -> 0.0033146014
A12: 1000 | B12: =('属性输入'!$N$19+'属性输入'!$O$19*('属性输入'!$B$25+A12-'属性输入'!$E$11+'属性输入'!$F$25-'属性输入'!$R$25+'属性输入'!$N$25-'属性输入'!$K$11+'属性输入'!$S$27))*(1-'属性输入'!$P$25)*(1+'属性输入'!$K$27-'属性输入'!$O$11)+(1+'属性输入'!$M$27-'属性输入'!$O$11)*'属性输入'!$O$19*(1-'属性输入'!$S$25)*'属性输入'!$E$25 -> 17387.81 | C12: =(B12-$B$2)/$B$2 -> 0.034165211 | D12: 0.1 | E12: =$E$2+A12 -> 18500 | F12: =(B13-B12)/B12 -> 0.0033036511
A13: 1100 | B13: =('属性输入'!$N$19+'属性输入'!$O$19*('属性输入'!$B$25+A13-'属性输入'!$E$11+'属性输入'!$F$25-'属性输入'!$R$25+'属性输入'!$N$25-'属性输入'!$K$11+'属性输入'!$S$27))*(1-'属性输入'!$P$25)*(1+'属性输入'!$K$27-'属性输入'!$O$11)+(1+'属性输入'!$M$27-'属性输入'!$O$11)*'属性输入'!$O$19*(1-'属性输入'!$S$25)*'属性输入'!$E$25 -> 17445.253 | C13: =(B13-$B$2)/$B$2 -> 0.037581732 | D13: 0.1 | E13: =$E$2+A13 -> 18600 | F13: =(B14-B13)/B13 -> 0.003292773
A14: 1200 | B14: =('属性输入'!$N$19+'属性输入'!$O$19*('属性输入'!$B$25+A14-'属性输入'!$E$11+'属性输入'!$F$25-'属性输入'!$R$25+'属性输入'!$N$25-'属性输入'!$K$11+'属性输入'!$S$27))*(1-'属性输入'!$P$25)*(1+'属性输入'!$K$27-'属性输入'!$O$11)+(1+'属性输入'!$M$27-'属性输入'!$O$11)*'属性输入'!$O$19*(1-'属性输入'!$S$25)*'属性输入'!$E$25 -> 17502.696 | C14: =(B14-$B$2)/$B$2 -> 0.040998253 | D14: 0.1 | E14: =$E$2+A14 -> 18700 | F14: =(B15-B14)/B14 -> 0.0032819662
A15: 1300 | B15: =('属性输入'!$N$19+'属性输入'!$O$19*('属性输入'!$B$25+A15-'属性输入'!$E$11+'属性输入'!$F$25-'属性输入'!$R$25+'属性输入'!$N$25-'属性输入'!$K$11+'属性输入'!$S$27))*(1-'属性输入'!$P$25)*(1+'属性输入'!$K$27-'属性输入'!$O$11)+(1+'属性输入'!$M$27-'属性输入'!$O$11)*'属性输入'!$O$19*(1-'属性输入'!$S$25)*'属性输入'!$E$25 -> 17560.14 | C15: =(B15-$B$2)/$B$2 -> 0.044414774 | D15: 0.1 | E15: =$E$2+A15 -> 18800 | F15: =(B16-B15)/B15 -> 0.0032712301
A16: 1400 | B16: =('属性输入'!$N$19+'属性输入'!$O$19*('属性输入'!$B$25+A16-'属性输入'!$E$11+'属性输入'!$F$25-'属性输入'!$R$25+'属性输入'!$N$25-'属性输入'!$K$11+'属性输入'!$S$27))*(1-'属性输入'!$P$25)*(1+'属性输入'!$K$27-'属性输入'!$O$11)+(1+'属性输入'!$M$27-'属性输入'!$O$11)*'属性输入'!$O$19*(1-'属性输入'!$S$25)*'属性输入'!$E$25 -> 17617.583 | C16: =(B16-$B$2)/$B$2 -> 0.047831295 | D16: 0.1 | E16: =$E$2+A16 -> 18900 | F16: =(B17-B16)/B16 -> 0.0032605641
A17: 1500 | B17: =('属性输入'!$N$19+'属性输入'!$O$19*('属性输入'!$B$25+A17-'属性输入'!$E$11+'属性输入'!$F$25-'属性输入'!$R$25+'属性输入'!$N$25-'属性输入'!$K$11+'属性输入'!$S$27))*(1-'属性输入'!$P$25)*(1+'属性输入'!$K$27-'属性输入'!$O$11)+(1+'属性输入'!$M$27-'属性输入'!$O$11)*'属性输入'!$O$19*(1-'属性输入'!$S$25)*'属性输入'!$E$25 -> 17675.026 | C17: =(B17-$B$2)/$B$2 -> 0.051247816 | D17: 0.1 | E17: =$E$2+A17 -> 19000 | F17: =(B18-B17)/B17 -> 0.0032499673
A18: 1600 | B18: =('属性输入'!$N$19+'属性输入'!$O$19*('属性输入'!$B$25+A18-'属性输入'!$E$11+'属性输入'!$F$25-'属性输入'!$R$25+'属性输入'!$N$25-'属性输入'!$K$11+'属性输入'!$S$27))*(1-'属性输入'!$P$25)*(1+'属性输入'!$K$27-'属性输入'!$O$11)+(1+'属性输入'!$M$27-'属性输入'!$O$11)*'属性输入'!$O$19*(1-'属性输入'!$S$25)*'属性输入'!$E$25 -> 17732.469 | C18: =(B18-$B$2)/$B$2 -> 0.054664337 | D18: 0.1 | E18: =$E$2+A18 -> 19100 | F18: =(B19-B18)/B18 -> 0.0032394393
A19: 1700 | B19: =('属性输入'!$N$19+'属性输入'!$O$19*('属性输入'!$B$25+A19-'属性输入'!$E$11+'属性输入'!$F$25-'属性输入'!$R$25+'属性输入'!$N$25-'属性输入'!$K$11+'属性输入'!$S$27))*(1-'属性输入'!$P$25)*(1+'属性输入'!$K$27-'属性输入'!$O$11)+(1+'属性输入'!$M$27-'属性输入'!$O$11)*'属性输入'!$O$19*(1-'属性输入'!$S$25)*'属性输入'!$E$25 -> 17789.913 | C19: =(B19-$B$2)/$B$2 -> 0.058080858 | D19: 0.1 | E19: =$E$2+A19 -> 19200 | F19: =(B20-B19)/B19 -> 0.0032289792
A20: 1800 | B20: =('属性输入'!$N$19+'属性输入'!$O$19*('属性输入'!$B$25+A20-'属性输入'!$E$11+'属性输入'!$F$25-'属性输入'!$R$25+'属性输入'!$N$25-'属性输入'!$K$11+'属性输入'!$S$27))*(1-'属性输入'!$P$25)*(1+'属性输入'!$K$27-'属性输入'!$O$11)+(1+'属性输入'!$M$27-'属性输入'!$O$11)*'属性输入'!$O$19*(1-'属性输入'!$S$25)*'属性输入'!$E$25 -> 17847.356 | C20: =(B20-$B$2)/$B$2 -> 0.061497379 | D20: 0.1 | E20: =$E$2+A20 -> 19300 | F20: =(B21-B20)/B20 -> 0.0032185864
A21: 1900 | B21: =('属性输入'!$N$19+'属性输入'!$O$19*('属性输入'!$B$25+A21-'属性输入'!$E$11+'属性输入'!$F$25-'属性输入'!$R$25+'属性输入'!$N$25-'属性输入'!$K$11+'属性输入'!$S$27))*(1-'属性输入'!$P$25)*(1+'属性输入'!$K$27-'属性输入'!$O$11)+(1+'属性输入'!$M$27-'属性输入'!$O$11)*'属性输入'!$O$19*(1-'属性输入'!$S$25)*'属性输入'!$E$25 -> 17904.799 | C21: =(B21-$B$2)/$B$2 -> 0.0649139 | D21: 0.1 | E21: =$E$2+A21 -> 19400 | F21: =(B22-B21)/B21 -> 0.0032082604
... A89: 8700 | B89: =('属性输入'!$N$19+'属性输入'!$O$19*('属性输入'!$B$25+A89-'属性输入'!$E$11+'属性输入'!$F$25-'属性输入'!$R$25+'属性输入'!$N$25-'属性输入'!$K$11+'属性输入'!$S$27))*(1-'属性输入'!$P$25)*(1+'属性输入'!$K$27-'属性输入'!$O$11)+(1+'属性输入'!$M$27-'属性输入'!$O$11)*'属性输入'!$O$19*(1-'属性输入'!$S$25)*'属性输入'!$E$25 -> 21810.941 | C89: =(B89-$B$2)/$B$2 -> 0.29723733 | D89: 0.1 | E89: =$E$2+A89 -> 26200 | F89: =(B90-B89)/B89 -> 0.0026336901
A90: 8800 | B90: =('属性输入'!$N$19+'属性输入'!$O$19*('属性输入'!$B$25+A90-'属性输入'!$E$11+'属性输入'!$F$25-'属性输入'!$R$25+'属性输入'!$N$25-'属性输入'!$K$11+'属性输入'!$S$27))*(1-'属性输入'!$P$25)*(1+'属性输入'!$K$27-'属性输入'!$O$11)+(1+'属性输入'!$M$27-'属性输入'!$O$11)*'属性输入'!$O$19*(1-'属性输入'!$S$25)*'属性输入'!$E$25 -> 21868.384 | C90: =(B90-$B$2)/$B$2 -> 0.30065385 | D90: 0.1 | E90: =$E$2+A90 -> 26300

Sheet 元素攻击提升收益
A1: 元素攻击提升 | B1: 伤害 | C1: 元素攻击提升伤害百分比 | D1: 元素攻击 | E1: 每增加50点元素攻击收益率 | F1: y=0.1 | O1: 元素攻击提升 | P1: 伤害 | Q1: 攻击 | R1: 每增加100点元素攻击收益率
A2: 0 | B2: =('属性输入'!$N$19+'属性输入'!$O$19*('属性输入'!$B$25-'属性输入'!$E$11+'属性输入'!$F$25-'属性输入'!$R$25+'属性输入'!$N$25-'属性输入'!$K$11+'属性输入'!$S$27))*(1-'属性输入'!$P$25)*(1+'属性输入'!$K$27-'属性输入'!$O$11)+(1+'属性输入'!$M$27-'属性输入'!$O$11)*'属性输入'!$O$19*(1-'属性输入'!$S$25)*('属性输入'!$E$25+A2) -> 16813.377 | C2: =(B2-$B$2)/$B$2 -> 0 | D2: ='属性输入'!$E$25 -> 6200 | E2: =(B3-B2)/B2 -> 0.0017993329 | F2: 0.1 | O2: 0 | P2: =('属性输入'!$N$19+'属性输入'!$O$19*('属性输入'!$B$25-'属性输入'!$E$11+'属性输入'!$F$25-'属性输入'!$R$25+'属性输入'!$N$25-'属性输入'!$K$11+'属性输入'!$S$27))*(1-'属性输入'!$P$25)*(1+'属性输入'!$K$27-'属性输入'!$O$11)+(1+'属性输入'!$M$27-'属性输入'!$O$11)*'属性输入'!$O$19*(1-'属性输入'!$S$25)*('属性输入'!$E$25+O2) -> 16813.377 | Q2: ='属性输入'!$E$25 -> 6200 | R2: =(P3-P2)/P2 -> 0.0035986657 | S2: 133元素收益
A3: 50 | B3: =('属性输入'!$N$19+'属性输入'!$O$19*('属性输入'!$B$25-'属性输入'!$E$11+'属性输入'!$F$25-'属性输入'!$R$25+'属性输入'!$N$25-'属性输入'!$K$11+'属性输入'!$S$27))*(1-'属性输入'!$P$25)*(1+'属性输入'!$K$27-'属性输入'!$O$11)+(1+'属性输入'!$M$27-'属性输入'!$O$11)*'属性输入'!$O$19*(1-'属性输入'!$S$25)*('属性输入'!$E$25+A3) -> 16843.63 | C3: =(B3-$B$2)/$B$2 -> 0.0017993329 | D3: =$D$2+A3 -> 6250 | E3: =(B4-B3)/B3 -> 0.0017961011 | F3: 0.1 | O3: 100 | P3: =('属性输入'!$N$19+'属性输入'!$O$19*('属性输入'!$B$25-'属性输入'!$E$11+'属性输入'!$F$25-'属性输入'!$R$25+'属性输入'!$N$25-'属性输入'!$K$11+'属性输入'!$S$27))*(1-'属性输入'!$P$25)*(1+'属性输入'!$K$27-'属性输入'!$O$11)+(1+'属性输入'!$M$27-'属性输入'!$O$11)*'属性输入'!$O$19*(1-'属性输入'!$S$25)*('属性输入'!$E$25+O3) -> 16873.883 | Q3: =$D$2+O3 -> 6300
A4: 100 | B4: =('属性输入'!$N$19+'属性输入'!$O$19*('属性输入'!$B$25-'属性输入'!$E$11+'属性输入'!$F$25-'属性输入'!$R$25+'属性输入'!$N$25-'属性输入'!$K$11+'属性输入'!$S$27))*(1-'属性输入'!$P$25)*(1+'属性输入'!$K$27-'属性输入'!$O$11)+(1+'属性输入'!$M$27-'属性输入'!$O$11)*'属性输入'!$O$19*(1-'属性输入'!$S$25)*('属性输入'!$E$25+A4) -> 16873.883 | C4: =(B4-$B$2)/$B$2 -> 0.0035986657 | D4: =$D$2+A4 -> 6300 | E4: =(B5-B4)/B4 -> 0.0017928809 | F4: 0.1 | O4: 159 | P4: =('属性输入'!$N$19+'属性输入'!$O$19*('属性输入'!$B$25-'属性输入'!$E$11+'属性输入'!$F$25-'属性输入'!$R$25+'属性输入'!$N$25-'属性输入'!$K$11+'属性输入'!$S$27))*(1-'属性输入'!$P$25)*(1+'属性输入'!$K$27-'属性输入'!$O$11)+(1+'属性输入'!$M$27-'属性输入'!$O$11)*'属性输入'!$O$19*(1-'属性输入'!$S$25)*('属性输入'!$E$25+O4) -> 16909.581 | Q4: =Q2+O4 -> 6359 | S4: =(P4-P2)/P2 -> 0.0057218785
A5: 150 | B5: =('属性输入'!$N$19+'属性输入'!$O$19*('属性输入'!$B$25-'属性输入'!$E$11+'属性输入'!$F$25-'属性输入'!$R$25+'属性输入'!$N$25-'属性输入'!$K$11+'属性输入'!$S$27))*(1-'属性输入'!$P$25)*(1+'属性输入'!$K$27-'属性输入'!$O$11)+(1+'属性输入'!$M$27-'属性输入'!$O$11)*'属性输入'!$O$19*(1-'属性输入'!$S$25)*('属性输入'!$E$25+A5) -> 16904.136 | C5: =(B5-$B$2)/$B$2 -> 0.0053979986 | D5: =$D$2+A5 -> 6350 | E5: =(B6-B5)/B5 -> 0.0017896722 | F5: 0.1
A6: 200 | B6: =('属性输入'!$N$19+'属性输入'!$O$19*('属性输入'!$B$25-'属性输入'!$E$11+'属性输入'!$F$25-'属性输入'!$R$25+'属性输入'!$N$25-'属性输入'!$K$11+'属性输入'!$S$27))*(1-'属性输入'!$P$25)*(1+'属性输入'!$K$27-'属性输入'!$O$11)+(1+'属性输入'!$M$27-'属性输入'!$O$11)*'属性输入'!$O$19*(1-'属性输入'!$S$25)*('属性输入'!$E$25+A6) -> 16934.389 | C6: =(B6-$B$2)/$B$2 -> 0.0071973314 | D6: =$D$2+A6 -> 6400 | E6: =(B7-B6)/B6 -> 0.001786475 | F6: 0.1
A7: 250 | B7: =('属性输入'!$N$19+'属性输入'!$O$19*('属性输入'!$B$25-'属性输入'!$E$11+'属性输入'!$F$25-'属性输入'!$R$25+'属性输入'!$N$25-'属性输入'!$K$11+'属性输入'!$S$27))*(1-'属性输入'!$P$25)*(1+'属性输入'!$K$27-'属性输入'!$O$11)+(1+'属性输入'!$M$27-'属性输入'!$O$11)*'属性输入'!$O$19*(1-'属性输入'!$S$25)*('属性输入'!$E$25+A7) -> 16964.642 | C7: =(B7-$B$2)/$B$2 -> 0.0089966643 | D7: =$D$2+A7 -> 6450 | E7: =(B8-B7)/B7 -> 0.0017832892 | F7: 0.1
A8: 300 | B8: =('属性输入'!$N$19+'属性输入'!$O$19*('属性输入'!$B$25-'属性输入'!$E$11+'属性输入'!$F$25-'属性输入'!$R$25+'属性输入'!$N$25-'属性输入'!$K$11+'属性输入'!$S$27))*(1-'属性输入'!$P$25)*(1+'属性输入'!$K$27-'属性输入'!$O$11)+(1+'属性输入'!$M$27-'属性输入'!$O$11)*'属性输入'!$O$19*(1-'属性输入'!$S$25)*('属性输入'!$E$25+A8) -> 16994.894 | C8: =(B8-$B$2)/$B$2 -> 0.010795997 | D8: =$D$2+A8 -> 6500 | E8: =(B9-B8)/B8 -> 0.0017801147 | F8: 0.1
A9: 350 | B9: =('属性输入'!$N$19+'属性输入'!$O$19*('属性输入'!$B$25-'属性输入'!$E$11+'属性输入'!$F$25-'属性输入'!$R$25+'属性输入'!$N$25-'属性输入'!$K$11+'属性输入'!$S$27))*(1-'属性输入'!$P$25)*(1+'属性输入'!$K$27-'属性输入'!$O$11)+(1+'属性输入'!$M$27-'属性输入'!$O$11)*'属性输入'!$O$19*(1-'属性输入'!$S$25)*('属性输入'!$E$25+A9) -> 17025.147 | C9: =(B9-$B$2)/$B$2 -> 0.01259533 | D9: =$D$2+A9 -> 6550 | E9: =(B10-B9)/B9 -> 0.0017769516 | F9: 0.1
A10: 400 | B10: =('属性输入'!$N$19+'属性输入'!$O$19*('属性输入'!$B$25-'属性输入'!$E$11+'属性输入'!$F$25-'属性输入'!$R$25+'属性输入'!$N$25-'属性输入'!$K$11+'属性输入'!$S$27))*(1-'属性输入'!$P$25)*(1+'属性输入'!$K$27-'属性输入'!$O$11)+(1+'属性输入'!$M$27-'属性输入'!$O$11)*'属性输入'!$O$19*(1-'属性输入'!$S$25)*('属性输入'!$E$25+A10) -> 17055.4 | C10: =(B10-$B$2)/$B$2 -> 0.014394663 | D10: =$D$2+A10 -> 6600 | E10: =(B11-B10)/B10 -> 0.0017737996 | F10: 0.1
A11: 450 | B11: =('属性输入'!$N$19+'属性输入'!$O$19*('属性输入'!$B$25-'属性输入'!$E$11+'属性输入'!$F$25-'属性输入'!$R$25+'属性输入'!$N$25-'属性输入'!$K$11+'属性输入'!$S$27))*(1-'属性输入'!$P$25)*(1+'属性输入'!$K$27-'属性输入'!$O$11)+(1+'属性输入'!$M$27-'属性输入'!$O$11)*'属性输入'!$O$19*(1-'属性输入'!$S$25)*('属性输入'!$E$25+A11) -> 17085.653 | C11: =(B11-$B$2)/$B$2 -> 0.016193996 | D11: =$D$2+A11 -> 6650 | E11: =(B12-B11)/B11 -> 0.0017706588 | F11: 0.1
A12: 500 | B12: =('属性输入'!$N$19+'属性输入'!$O$19*('属性输入'!$B$25-'属性输入'!$E$11+'属性输入'!$F$25-'属性输入'!$R$25+'属性输入'!$N$25-'属性输入'!$K$11+'属性输入'!$S$27))*(1-'属性输入'!$P$25)*(1+'属性输入'!$K$27-'属性输入'!$O$11)+(1+'属性输入'!$M$27-'属性输入'!$O$11)*'属性输入'!$O$19*(1-'属性输入'!$S$25)*('属性输入'!$E$25+A12) -> 17115.906 | C12: =(B12-$B$2)/$B$2 -> 0.017993329 | D12: =$D$2+A12 -> 6700 | E12: =(B13-B12)/B12 -> 0.0017675291 | F12: 0.1
A13: 550 | B13: =('属性输入'!$N$19+'属性输入'!$O$19*('属性输入'!$B$25-'属性输入'!$E$11+'属性输入'!$F$25-'属性输入'!$R$25+'属性输入'!$N$25-'属性输入'!$K$11+'属性输入'!$S$27))*(1-'属性输入'!$P$25)*(1+'属性输入'!$K$27-'属性输入'!$O$11)+(1+'属性输入'!$M$27-'属性输入'!$O$11)*'属性输入'!$O$19*(1-'属性输入'!$S$25)*('属性输入'!$E$25+A13) -> 17146.159 | C13: =(B13-$B$2)/$B$2 -> 0.019792661 | D13: =$D$2+A13 -> 6750 | E13: =(B14-B13)/B13 -> 0.0017644105 | F13: 0.1
A14: 600 | B14: =('属性输入'!$N$19+'属性输入'!$O$19*('属性输入'!$B$25-'属性输入'!$E$11+'属性输入'!$F$25-'属性输入'!$R$25+'属性输入'!$N$25-'属性输入'!$K$11+'属性输入'!$S$27))*(1-'属性输入'!$P$25)*(1+'属性输入'!$K$27-'属性输入'!$O$11)+(1+'属性输入'!$M$27-'属性输入'!$O$11)*'属性输入'!$O$19*(1-'属性输入'!$S$25)*('属性输入'!$E$25+A14) -> 17176.412 | C14: =(B14-$B$2)/$B$2 -> 0.021591994 | D14: =$D$2+A14 -> 6800 | E14: =(B15-B14)/B14 -> 0.0017613028 | F14: 0.1
A15: 650 | B15: =('属性输入'!$N$19+'属性输入'!$O$19*('属性输入'!$B$25-'属性输入'!$E$11+'属性输入'!$F$25-'属性输入'!$R$25+'属性输入'!$N$25-'属性输入'!$K$11+'属性输入'!$S$27))*(1-'属性输入'!$P$25)*(1+'属性输入'!$K$27-'属性输入'!$O$11)+(1+'属性输入'!$M$27-'属性输入'!$O$11)*'属性输入'!$O$19*(1-'属性输入'!$S$25)*('属性输入'!$E$25+A15) -> 17206.665 | C15: =(B15-$B$2)/$B$2 -> 0.023391327 | D15: =$D$2+A15 -> 6850 | E15: =(B16-B15)/B15 -> 0.0017582061 | F15: 0.1
A16: 700 | B16: =('属性输入'!$N$19+'属性输入'!$O$19*('属性输入'!$B$25-'属性输入'!$E$11+'属性输入'!$F$25-'属性输入'!$R$25+'属性输入'!$N$25-'属性输入'!$K$11+'属性输入'!$S$27))*(1-'属性输入'!$P$25)*(1+'属性输入'!$K$27-'属性输入'!$O$11)+(1+'属性输入'!$M$27-'属性输入'!$O$11)*'属性输入'!$O$19*(1-'属性输入'!$S$25)*('属性输入'!$E$25+A16) -> 17236.917 | C16: =(B16-$B$2)/$B$2 -> 0.02519066 | D16: =$D$2+A16 -> 6900 | E16: =(B17-B16)/B16 -> 0.0017551202 | F16: 0.1
... A49: 2350 | B49: =('属性输入'!$N$19+'属性输入'!$O$19*('属性输入'!$B$25-'属性输入'!$E$11+'属性输入'!$F$25-'属性输入'!$R$25+'属性输入'!$N$25-'属性输入'!$K$11+'属性输入'!$S$27))*(1-'属性输入'!$P$25)*(1+'属性输入'!$K$27-'属性输入'!$O$11)+(1+'属性输入'!$M$27-'属性输入'!$O$11)*'属性输入'!$O$19*(1-'属性输入'!$S$25)*('属性输入'!$E$25+A49) -> 18235.262 | C49: =(B49-$B$2)/$B$2 -> 0.084568645 | D49: =$D$2+A49 -> 8550 | E49: =(B50-B49)/B49 -> 0.0016590309 | F49: 0.1
A50: 2400 | B50: =('属性输入'!$N$19+'属性输入'!$O$19*('属性输入'!$B$25-'属性输入'!$E$11+'属性输入'!$F$25-'属性输入'!$R$25+'属性输入'!$N$25-'属性输入'!$K$11+'属性输入'!$S$27))*(1-'属性输入'!$P$25)*(1+'属性输入'!$K$27-'属性输入'!$O$11)+(1+'属性输入'!$M$27-'属性输入'!$O$11)*'属性输入'!$O$19*(1-'属性输入'!$S$25)*('属性输入'!$E$25+A50) -> 18265.515 | C50: =(B50-$B$2)/$B$2 -> 0.086367977 | D50: =$D$2+A50 -> 8600 | F50: 0.1

Sheet 破防提升收益
A1: 破防提升 | B1: 剩余防御 | C1: 防御减免 | D1: 伤害计算 | E1: 伤害提升百分比 | F1: y=0.1 | G1: 破防 | H1: 每增加150点破防收益率 | V1: 破防提升 | W1: 剩余防御 | X1: 防御减免 | Y1: 伤害计算 | Z1: 每增加100点破防收益率
A2: 0 | B2: =MAX('属性输入'!$B$11-A2-'属性输入'!$C$25,0) -> 5500 | C2: =(0.1+B2/(B2+19032)) -> 0.32419697 | D2: =('属性输入'!$N$19+'属性输入'!$O$19*('属性输入'!$B$25-'属性输入'!$E$11+'属性输入'!$F$25-'属性输入'!$R$25+'属性输入'!$N$25-'属性输入'!$K$11+'属性输入'!$S$27))*(1-C2)*(1+'属性输入'!$K$27-'属性输入'!$O$11)+(1+'属性输入'!$M$27-'属性输入'!$O$11)*'属性输入'!$O$19*(1-'属性输入'!$S$25)*'属性输入'!$E$25 -> 16813.377 | E2: =(D2-$D$2)/$D$2 -> 0 | F2: 0.1 | G2: ='属性输入'!$C$25+A2 -> 13000 | H2: =(D3-D2)/D2 -> 0.0054866687 | V2: 0 | W2: =MAX('属性输入'!$B$11-V2-'属性输入'!$C$25,0) -> 5500 | X2: =(0.1+W2/(W2+19032)) -> 0.32419697 | Y2: =('属性输入'!$N$19+'属性输入'!$O$19*('属性输入'!$B$25-'属性输入'!$E$11+'属性输入'!$F$25-'属性输入'!$R$25+'属性输入'!$N$25-'属性输入'!$K$11+'属性输入'!$S$27))*(1-X2)*(1+'属性输入'!$K$27-'属性输入'!$O$11)+(1+'属性输入'!$M$27-'属性输入'!$O$11)*'属性输入'!$O$19*(1-'属性输入'!$S$25)*'属性输入'!$E$25 -> 16813.377 | Z2: =(Y3-Y2)/Y2 -> 0.0036502935 | AA2: 破防增328收益
A3: 150 | B3: =MAX('属性输入'!$B$11-A3-'属性输入'!$C$25,0) -> 5350 | C3: =(0.1+B3/(B3+19032)) -> 0.31942417 | D3: =('属性输入'!$N$19+'属性输入'!$O$19*('属性输入'!$B$25-'属性输入'!$E$11+'属性输入'!$F$25-'属性输入'!$R$25+'属性输入'!$N$25-'属性输入'!$K$11+'属性输入'!$S$27))*(1-C3)*(1+'属性输入'!$K$27-'属性输入'!$O$11)+(1+'属性输入'!$M$27-'属性输入'!$O$11)*'属性输入'!$O$19*(1-'属性输入'!$S$25)*'属性输入'!$E$25 -> 16905.627 | E3: =(D3-$D$2)/$D$2 -> 0.0054866687 | F3: 0.1 | G3: ='属性输入'!$C$25+A3 -> 13150 | H3: =(D4-D3)/D3 -> 0.0055242855 | V3: 100 | W3: =MAX('属性输入'!$B$11-V3-'属性输入'!$C$25,0) -> 5400 | X3: =(0.1+W3/(W3+19032)) -> 0.32102161 | Y3: =('属性输入'!$N$19+'属性输入'!$O$19*('属性输入'!$B$25-'属性输入'!$E$11+'属性输入'!$F$25-'属性输入'!$R$25+'属性输入'!$N$25-'属性输入'!$K$11+'属性输入'!$S$27))*(1-X3)*(1+'属性输入'!$K$27-'属性输入'!$O$11)+(1+'属性输入'!$M$27-'属性输入'!$O$11)*'属性输入'!$O$19*(1-'属性输入'!$S$25)*'属性输入'!$E$25 -> 16874.751
A4: 300 | B4: =MAX('属性输入'!$B$11-A4-'属性输入'!$C$25,0) -> 5200 | C4: =(0.1+B4/(B4+19032)) -> 0.31459227 | D4: =('属性输入'!$N$19+'属性输入'!$O$19*('属性输入'!$B$25-'属性输入'!$E$11+'属性输入'!$F$25-'属性输入'!$R$25+'属性输入'!$N$25-'属性输入'!$K$11+'属性输入'!$S$27))*(1-C4)*(1+'属性输入'!$K$27-'属性输入'!$O$11)+(1+'属性输入'!$M$27-'属性输入'!$O$11)*'属性输入'!$O$19*(1-'属性输入'!$S$25)*'属性输入'!$E$25 -> 16999.018 | E4: =(D4-$D$2)/$D$2 -> 0.011041264 | F4: 0.1 | G4: ='属性输入'!$C$25+A4 -> 13300 | H4: =(D5-D4)/D4 -> 0.0055623757 | V4: 393 | W4: =MAX('属性输入'!$B$11-V4-'属性输入'!$C$25,0) -> 5107 | X4: =(0.1+W4/(W4+19032)) -> 0.31156634 | Y4: =('属性输入'!$N$19+'属性输入'!$O$19*('属性输入'!$B$25-'属性输入'!$E$11+'属性输入'!$F$25-'属性输入'!$R$25+'属性输入'!$N$25-'属性输入'!$K$11+'属性输入'!$S$27))*(1-X4)*(1+'属性输入'!$K$27-'属性输入'!$O$11)+(1+'属性输入'!$M$27-'属性输入'!$O$11)*'属性输入'!$O$19*(1-'属性输入'!$S$25)*'属性输入'!$E$25 -> 17057.504 | AA4: =(Y4-Y2)/Y2 -> 0.014519781
A5: 450 | B5: =MAX('属性输入'!$B$11-A5-'属性输入'!$C$25,0) -> 5050 | C5: =(0.1+B5/(B5+19032)) -> 0.30970019 | D5: =('属性输入'!$N$19+'属性输入'!$O$19*('属性输入'!$B$25-'属性输入'!$E$11+'属性输入'!$F$25-'属性输入'!$R$25+'属性输入'!$N$25-'属性输入'!$K$11+'属性输入'!$S$27))*(1-C5)*(1+'属性输入'!$K$27-'属性输入'!$O$11)+(1+'属性输入'!$M$27-'属性输入'!$O$11)*'属性输入'!$O$19*(1-'属性输入'!$S$25)*'属性输入'!$E$25 -> 17093.573 | E5: =(D5-$D$2)/$D$2 -> 0.016665055 | F5: 0.1 | G5: ='属性输入'!$C$25+A5 -> 13450 | H5: =(D6-D5)/D5 -> 0.0056009484
A6: 600 | B6: =MAX('属性输入'!$B$11-A6-'属性输入'!$C$25,0) -> 4900 | C6: =(0.1+B6/(B6+19032)) -> 0.30474678 | D6: =('属性输入'!$N$19+'属性输入'!$O$19*('属性输入'!$B$25-'属性输入'!$E$11+'属性输入'!$F$25-'属性输入'!$R$25+'属性输入'!$N$25-'属性输入'!$K$11+'属性输入'!$S$27))*(1-C6)*(1+'属性输入'!$K$27-'属性输入'!$O$11)+(1+'属性输入'!$M$27-'属性输入'!$O$11)*'属性输入'!$O$19*(1-'属性输入'!$S$25)*'属性输入'!$E$25 -> 17189.313 | E6: =(D6-$D$2)/$D$2 -> 0.022359344 | F6: 0.1 | G6: ='属性输入'!$C$25+A6 -> 13600 | H6: =(D7-D6)/D6 -> 0.0056400126
A7: 750 | B7: =MAX('属性输入'!$B$11-A7-'属性输入'!$C$25,0) -> 4750 | C7: =(0.1+B7/(B7+19032)) -> 0.29973089 | D7: =('属性输入'!$N$19+'属性输入'!$O$19*('属性输入'!$B$25-'属性输入'!$E$11+'属性输入'!$F$25-'属性输入'!$R$25+'属性输入'!$N$25-'属性输入'!$K$11+'属性输入'!$S$27))*(1-C7)*(1+'属性输入'!$K$27-'属性输入'!$O$11)+(1+'属性输入'!$M$27-'属性输入'!$O$11)*'属性输入'!$O$19*(1-'属性输入'!$S$25)*'属性输入'!$E$25 -> 17286.261 | E7: =(D7-$D$2)/$D$2 -> 0.028125464 | F7: 0.1 | G7: ='属性输入'!$C$25+A7 -> 13750 | H7: =(D8-D7)/D7 -> 0.0056795777
A8: 900 | B8: =MAX('属性输入'!$B$11-A8-'属性输入'!$C$25,0) -> 4600 | C8: =(0.1+B8/(B8+19032)) -> 0.29465132 | D8: =('属性输入'!$N$19+'属性输入'!$O$19*('属性输入'!$B$25-'属性输入'!$E$11+'属性输入'!$F$25-'属性输入'!$R$25+'属性输入'!$N$25-'属性输入'!$K$11+'属性输入'!$S$27))*(1-C8)*(1+'属性输入'!$K$27-'属性输入'!$O$11)+(1+'属性输入'!$M$27-'属性输入'!$O$11)*'属性输入'!$O$19*(1-'属性输入'!$S$25)*'属性输入'!$E$25 -> 17384.44 | E8: =(D8-$D$2)/$D$2 -> 0.033964782 | F8: 0.1 | G8: ='属性输入'!$C$25+A8 -> 13900 | H8: =(D9-D8)/D8 -> 0.0057196533
A9: 1050 | B9: =MAX('属性输入'!$B$11-A9-'属性输入'!$C$25,0) -> 4450 | C9: =(0.1+B9/(B9+19032)) -> 0.28950686 | D9: =('属性输入'!$N$19+'属性输入'!$O$19*('属性输入'!$B$25-'属性输入'!$E$11+'属性输入'!$F$25-'属性输入'!$R$25+'属性输入'!$N$25-'属性输入'!$K$11+'属性输入'!$S$27))*(1-C9)*(1+'属性输入'!$K$27-'属性输入'!$O$11)+(1+'属性输入'!$M$27-'属性输入'!$O$11)*'属性输入'!$O$19*(1-'属性输入'!$S$25)*'属性输入'!$E$25 -> 17483.873 | E9: =(D9-$D$2)/$D$2 -> 0.039878702 | F9: 0.1 | G9: ='属性输入'!$C$25+A9 -> 14050 | H9: =(D10-D9)/D9 -> 0.0057602493
A10: 1200 | B10: =MAX('属性输入'!$B$11-A10-'属性输入'!$C$25,0) -> 4300 | C10: =(0.1+B10/(B10+19032)) -> 0.28429625 | D10: =('属性输入'!$N$19+'属性输入'!$O$19*('属性输入'!$B$25-'属性输入'!$E$11+'属性输入'!$F$25-'属性输入'!$R$25+'属性输入'!$N$25-'属性输入'!$K$11+'属性输入'!$S$27))*(1-C10)*(1+'属性输入'!$K$27-'属性输入'!$O$11)+(1+'属性输入'!$M$27-'属性输入'!$O$11)*'属性输入'!$O$19*(1-'属性输入'!$S$25)*'属性输入'!$E$25 -> 17584.584 | E10: =(D10-$D$2)/$D$2 -> 0.045868663 | F10: 0.1 | G10: ='属性输入'!$C$25+A10 -> 14200 | H10: =(D11-D10)/D10 -> 0.0058013758
A11: 1350 | B11: =MAX('属性输入'!$B$11-A11-'属性输入'!$C$25,0) -> 4150 | C11: =(0.1+B11/(B11+19032)) -> 0.2790182 | D11: =('属性输入'!$N$19+'属性输入'!$O$19*('属性输入'!$B$25-'属性输入'!$E$11+'属性输入'!$F$25-'属性输入'!$R$25+'属性输入'!$N$25-'属性输入'!$K$11+'属性输入'!$S$27))*(1-C11)*(1+'属性输入'!$K$27-'属性输入'!$O$11)+(1+'属性输入'!$M$27-'属性输入'!$O$11)*'属性输入'!$O$19*(1-'属性输入'!$S$25)*'属性输入'!$E$25 -> 17686.599 | E11: =(D11-$D$2)/$D$2 -> 0.05193614 | F11: 0.1 | G11: ='属性输入'!$C$25+A11 -> 14350 | H11: =(D12-D11)/D11 -> 0.0058430431
A12: 1500 | B12: =MAX('属性输入'!$B$11-A12-'属性输入'!$C$25,0) -> 4000 | C12: =(0.1+B12/(B12+19032)) -> 0.27367141 | D12: =('属性输入'!$N$19+'属性输入'!$O$19*('属性输入'!$B$25-'属性输入'!$E$11+'属性输入'!$F$25-'属性输入'!$R$25+'属性输入'!$N$25-'属性输入'!$K$11+'属性输入'!$S$27))*(1-C12)*(1+'属性输入'!$K$27-'属性输入'!$O$11)+(1+'属性输入'!$M$27-'属性输入'!$O$11)*'属性输入'!$O$19*(1-'属性输入'!$S$25)*'属性输入'!$E$25 -> 17789.943 | E12: =(D12-$D$2)/$D$2 -> 0.058082648 | F12: 0.1 | G12: ='属性输入'!$C$25+A12 -> 14500 | H12: =(D13-D12)/D12 -> 0.0058852619
A13: 1650 | B13: =MAX('属性输入'!$B$11-A13-'属性输入'!$C$25,0) -> 3850 | C13: =(0.1+B13/(B13+19032)) -> 0.26825452 | D13: =('属性输入'!$N$19+'属性输入'!$O$19*('属性输入'!$B$25-'属性输入'!$E$11+'属性输入'!$F$25-'属性输入'!$R$25+'属性输入'!$N$25-'属性输入'!$K$11+'属性输入'!$S$27))*(1-C13)*(1+'属性输入'!$K$27-'属性输入'!$O$11)+(1+'属性输入'!$M$27-'属性输入'!$O$11)*'属性输入'!$O$19*(1-'属性输入'!$S$25)*'属性输入'!$E$25 -> 17894.641 | E13: =(D13-$D$2)/$D$2 -> 0.064309742 | F13: 0.1 | G13: ='属性输入'!$C$25+A13 -> 14650 | H13: =(D14-D13)/D13 -> 0.0059280431
A14: 1800 | B14: =MAX('属性输入'!$B$11-A14-'属性输入'!$C$25,0) -> 3700 | C14: =(0.1+B14/(B14+19032)) -> 0.26276614 | D14: =('属性输入'!$N$19+'属性输入'!$O$19*('属性输入'!$B$25-'属性输入'!$E$11+'属性输入'!$F$25-'属性输入'!$R$25+'属性输入'!$N$25-'属性输入'!$K$11+'属性输入'!$S$27))*(1-C14)*(1+'属性输入'!$K$27-'属性输入'!$O$11)+(1+'属性输入'!$M$27-'属性输入'!$O$11)*'属性输入'!$O$19*(1-'属性输入'!$S$25)*'属性输入'!$E$25 -> 18000.721 | E14: =(D14-$D$2)/$D$2 -> 0.070619016 | F14: 0.1 | G14: ='属性输入'!$C$25+A14 -> 14800 | H14: =(D15-D14)/D14 -> 0.0059713979
A15: 1950 | B15: =MAX('属性输入'!$B$11-A15-'属性输入'!$C$25,0) -> 3550 | C15: =(0.1+B15/(B15+19032)) -> 0.25720485 | D15: =('属性输入'!$N$19+'属性输入'!$O$19*('属性输入'!$B$25-'属性输入'!$E$11+'属性输入'!$F$25-'属性输入'!$R$25+'属性输入'!$N$25-'属性输入'!$K$11+'属性输入'!$S$27))*(1-C15)*(1+'属性输入'!$K$27-'属性输入'!$O$11)+(1+'属性输入'!$M$27-'属性输入'!$O$11)*'属性输入'!$O$19*(1-'属性输入'!$S$25)*'属性输入'!$E$25 -> 18108.211 | E15: =(D15-$D$2)/$D$2 -> 0.077012108 | F15: 0.1 | G15: ='属性输入'!$C$25+A15 -> 14950 | H15: =(D16-D15)/D15 -> 0.0060153379
A16: 2100 | B16: =MAX('属性输入'!$B$11-A16-'属性输入'!$C$25,0) -> 3400 | C16: =(0.1+B16/(B16+19032)) -> 0.25156919 | D16: =('属性输入'!$N$19+'属性输入'!$O$19*('属性输入'!$B$25-'属性输入'!$E$11+'属性输入'!$F$25-'属性输入'!$R$25+'属性输入'!$N$25-'属性输入'!$K$11+'属性输入'!$S$27))*(1-C16)*(1+'属性输入'!$K$27-'属性输入'!$O$11)+(1+'属性输入'!$M$27-'属性输入'!$O$11)*'属性输入'!$O$19*(1-'属性输入'!$S$25)*'属性输入'!$E$25 -> 18217.138 | E16: =(D16-$D$2)/$D$2 -> 0.083490699 | F16: 0.1 | G16: ='属性输入'!$C$25+A16 -> 15100 | H16: =(D17-D16)/D16 -> 0.006059875
... A18: 2400 | B18: =MAX('属性输入'!$B$11-A18-'属性输入'!$C$25,0) -> 3100 | C18: =(0.1+B18/(B18+19032)) -> 0.24006868 | D18: =('属性输入'!$N$19+'属性输入'!$O$19*('属性输入'!$B$25-'属性输入'!$E$11+'属性输入'!$F$25-'属性输入'!$R$25+'属性输入'!$N$25-'属性输入'!$K$11+'属性输入'!$S$27))*(1-C18)*(1+'属性输入'!$K$27-'属性输入'!$O$11)+(1+'属性输入'!$M$27-'属性输入'!$O$11)*'属性输入'!$O$19*(1-'属性输入'!$S$25)*'属性输入'!$E$25 -> 18439.421 | E18: =(D18-$D$2)/$D$2 -> 0.096711336 | F18: 0.1 | G18: ='属性输入'!$C$25+A18 -> 15400 | H18: =(D19-D18)/D18 -> 0.0061507889
A19: 2550 | B19: =MAX('属性输入'!$B$11-A19-'属性输入'!$C$25,0) -> 2950 | C19: =(0.1+B19/(B19+19032)) -> 0.23420071 | D19: =('属性输入'!$N$19+'属性输入'!$O$19*('属性输入'!$B$25-'属性输入'!$E$11+'属性输入'!$F$25-'属性输入'!$R$25+'属性输入'!$N$25-'属性输入'!$K$11+'属性输入'!$S$27))*(1-C19)*(1+'属性输入'!$K$27-'属性输入'!$O$11)+(1+'属性输入'!$M$27-'属性输入'!$O$11)*'属性输入'!$O$19*(1-'属性输入'!$S$25)*'属性输入'!$E$25 -> 18552.838 | E19: =(D19-$D$2)/$D$2 -> 0.10345698 | F19: 0.1 | G19: ='属性输入'!$C$25+A19 -> 15550

Sheet 命中提升收益
A1: 命中提升 | B1: 命中 | C1: 命中率 | D1: 伤害期望计算 | E1: 伤害提升百分比 | F1: 每增加21点命中收益率 | G1: y=0.1 | Q1: 命中提升 | R1: 命中 | S1: 命中率 | T1: 伤害期望计算 | U1: 伤害提升百分比 | V1: 每增加40点命中收益率
A2: 0 | B2: =A2+'属性输入'!$G$25 -> 4400 | C2: =MIN((143*(B2-'属性输入'!$F$11)/(B2-'属性输入'!F$11+10688)+95)/100,1) -> 1 | D2: ='属性输入'!$B$27*C2*(1+('属性输入'!$I$25-'属性输入'!$J$11)*'属性输入'!$P$27)+0.5*'属性输入'!$B$27*(1-C2) -> 19644.359 | E2: =(D2-$D$2)/$D$2 -> 0 | F2: =(D3-D2)/D2 -> 0 | G2: 0.1 | Q2: 0 | R2: =Q2+'属性输入'!$G$25 -> 4400 | S2: =MIN((143*(R2-'属性输入'!$F$11)/(R2-'属性输入'!$F$11+10688)+95)/100,1) -> 1 | T2: ='属性输入'!$B$27*S2*(1+('属性输入'!$I$25-'属性输入'!$J$11)*'属性输入'!$P$27)+0.5*'属性输入'!$B$27*(1-S2) -> 19644.359 | U2: =(T2-$D$2)/$D$2 -> 0 | V2: =(T3-T2)/T2 -> 0
A3: 21 | B3: =A3+'属性输入'!$G$25 -> 4421 | C3: =MIN((143*(B3-'属性输入'!$F$11)/(B3-'属性输入'!F$11+10688)+95)/100,1) -> 1 | D3: ='属性输入'!$B$27*C3*(1+('属性输入'!$I$25-'属性输入'!$J$11)*'属性输入'!$P$27)+0.5*'属性输入'!$B$27*(1-C3) -> 19644.359 | E3: =(D3-$D$2)/$D$2 -> 0 | F3: =(D4-D3)/D3 -> 0 | G3: 0.1 | Q3: 40 | R3: =Q3+'属性输入'!$G$25 -> 4440 | S3: =MIN((143*(R3-'属性输入'!$F$11)/(R3-'属性输入'!$F$11+10688)+95)/100,1) -> 1 | T3: ='属性输入'!$B$27*S3*(1+('属性输入'!$I$25-'属性输入'!$J$11)*'属性输入'!$P$27)+0.5*'属性输入'!$B$27*(1-S3) -> 19644.359 | U3: =(T3-$D$2)/$D$2 -> 0
A4: 42 | B4: =A4+'属性输入'!$G$25 -> 4442 | C4: =MIN((143*(B4-'属性输入'!$F$11)/(B4-'属性输入'!F$11+10688)+95)/100,1) -> 1 | D4: ='属性输入'!$B$27*C4*(1+('属性输入'!$I$25-'属性输入'!$J$11)*'属性输入'!$P$27)+0.5*'属性输入'!$B$27*(1-C4) -> 19644.359 | E4: =(D4-$D$2)/$D$2 -> 0 | F4: =(D5-D4)/D4 -> 0 | G4: 0.1 | Q4: 116 | R4: =R2+Q4 -> 4516 | S4: =MIN((143*(R4-'属性输入'!$F$11)/(R4-'属性输入'!$F$11+10688)+95)/100,1) -> 1 | T4: ='属性输入'!$B$27*S4*(1+('属性输入'!$I$25-'属性输入'!$J$11)*'属性输入'!$P$27)+0.5*'属性输入'!$B$27*(1-S4) -> 19644.359 | U4: =(T4-$D$2)/$D$2 -> 0
A5: 63 | B5: =A5+'属性输入'!$G$25 -> 4463 | C5: =MIN((143*(B5-'属性输入'!$F$11)/(B5-'属性输入'!F$11+10688)+95)/100,1) -> 1 | D5: ='属性输入'!$B$27*C5*(1+('属性输入'!$I$25-'属性输入'!$J$11)*'属性输入'!$P$27)+0.5*'属性输入'!$B$27*(1-C5) -> 19644.359 | E5: =(D5-$D$2)/$D$2 -> 0 | F5: =(D6-D5)/D5 -> 0 | G5: 0.1
A6: 84 | B6: =A6+'属性输入'!$G$25 -> 4484 | C6: =MIN((143*(B6-'属性输入'!$F$11)/(B6-'属性输入'!F$11+10688)+95)/100,1) -> 1 | D6: ='属性输入'!$B$27*C6*(1+('属性输入'!$I$25-'属性输入'!$J$11)*'属性输入'!$P$27)+0.5*'属性输入'!$B$27*(1-C6) -> 19644.359 | E6: =(D6-$D$2)/$D$2 -> 0 | F6: =(D7-D6)/D6 -> 0 | G6: 0.1
A7: 105 | B7: =A7+'属性输入'!$G$25 -> 4505 | C7: =MIN((143*(B7-'属性输入'!$F$11)/(B7-'属性输入'!F$11+10688)+95)/100,1) -> 1 | D7: ='属性输入'!$B$27*C7*(1+('属性输入'!$I$25-'属性输入'!$J$11)*'属性输入'!$P$27)+0.5*'属性输入'!$B$27*(1-C7) -> 19644.359 | E7: =(D7-$D$2)/$D$2 -> 0 | F7: =(D8-D7)/D7 -> 0 | G7: 0.1
A8: 126 | B8: =A8+'属性输入'!$G$25 -> 4526 | C8: =MIN((143*(B8-'属性输入'!$F$11)/(B8-'属性输入'!F$11+10688)+95)/100,1) -> 1 | D8: ='属性输入'!$B$27*C8*(1+('属性输入'!$I$25-'属性输入'!$J$11)*'属性输入'!$P$27)+0.5*'属性输入'!$B$27*(1-C8) -> 19644.359 | E8: =(D8-$D$2)/$D$2 -> 0 | F8: =(D9-D8)/D8 -> 0 | G8: 0.1
A9: 147 | B9: =A9+'属性输入'!$G$25 -> 4547 | C9: =MIN((143*(B9-'属性输入'!$F$11)/(B9-'属性输入'!F$11+10688)+95)/100,1) -> 1 | D9: ='属性输入'!$B$27*C9*(1+('属性输入'!$I$25-'属性输入'!$J$11)*'属性输入'!$P$27)+0.5*'属性输入'!$B$27*(1-C9) -> 19644.359 | E9: =(D9-$D$2)/$D$2 -> 0 | F9: =(D10-D9)/D9 -> 0 | G9: 0.1
A10: 168 | B10: =A10+'属性输入'!$G$25 -> 4568 | C10: =MIN((143*(B10-'属性输入'!$F$11)/(B10-'属性输入'!F$11+10688)+95)/100,1) -> 1 | D10: ='属性输入'!$B$27*C10*(1+('属性输入'!$I$25-'属性输入'!$J$11)*'属性输入'!$P$27)+0.5*'属性输入'!$B$27*(1-C10) -> 19644.359 | E10: =(D10-$D$2)/$D$2 -> 0 | F10: =(D11-D10)/D10 -> 0 | G10: 0.1
A11: 189 | B11: =A11+'属性输入'!$G$25 -> 4589 | C11: =MIN((143*(B11-'属性输入'!$F$11)/(B11-'属性输入'!F$11+10688)+95)/100,1) -> 1 | D11: ='属性输入'!$B$27*C11*(1+('属性输入'!$I$25-'属性输入'!$J$11)*'属性输入'!$P$27)+0.5*'属性输入'!$B$27*(1-C11) -> 19644.359 | E11: =(D11-$D$2)/$D$2 -> 0 | F11: =(D12-D11)/D11 -> 0 | G11: 0.1
A12: 210 | B12: =A12+'属性输入'!$G$25 -> 4610 | C12: =MIN((143*(B12-'属性输入'!$F$11)/(B12-'属性输入'!F$11+10688)+95)/100,1) -> 1 | D12: ='属性输入'!$B$27*C12*(1+('属性输入'!$I$25-'属性输入'!$J$11)*'属性输入'!$P$27)+0.5*'属性输入'!$B$27*(1-C12) -> 19644.359 | E12: =(D12-$D$2)/$D$2 -> 0 | F12: =(D13-D12)/D12 -> 0 | G12: 0.1
A13: 231 | B13: =A13+'属性输入'!$G$25 -> 4631 | C13: =MIN((143*(B13-'属性输入'!$F$11)/(B13-'属性输入'!F$11+10688)+95)/100,1) -> 1 | D13: ='属性输入'!$B$27*C13*(1+('属性输入'!$I$25-'属性输入'!$J$11)*'属性输入'!$P$27)+0.5*'属性输入'!$B$27*(1-C13) -> 19644.359 | E13: =(D13-$D$2)/$D$2 -> 0 | F13: =(D14-D13)/D13 -> 0 | G13: 0.1
A14: 252 | B14: =A14+'属性输入'!$G$25 -> 4652 | C14: =MIN((143*(B14-'属性输入'!$F$11)/(B14-'属性输入'!F$11+10688)+95)/100,1) -> 1 | D14: ='属性输入'!$B$27*C14*(1+('属性输入'!$I$25-'属性输入'!$J$11)*'属性输入'!$P$27)+0.5*'属性输入'!$B$27*(1-C14) -> 19644.359 | E14: =(D14-$D$2)/$D$2 -> 0 | F14: =(D15-D14)/D14 -> 0 | G14: 0.1
A15: 273 | B15: =A15+'属性输入'!$G$25 -> 4673 | C15: =MIN((143*(B15-'属性输入'!$F$11)/(B15-'属性输入'!F$11+10688)+95)/100,1) -> 1 | D15: ='属性输入'!$B$27*C15*(1+('属性输入'!$I$25-'属性输入'!$J$11)*'属性输入'!$P$27)+0.5*'属性输入'!$B$27*(1-C15) -> 19644.359 | E15: =(D15-$D$2)/$D$2 -> 0 | F15: =(D16-D15)/D15 -> 0 | G15: 0.1
A16: 294 | B16: =A16+'属性输入'!$G$25 -> 4694 | C16: =MIN((143*(B16-'属性输入'!$F$11)/(B16-'属性输入'!F$11+10688)+95)/100,1) -> 1 | D16: ='属性输入'!$B$27*C16*(1+('属性输入'!$I$25-'属性输入'!$J$11)*'属性输入'!$P$27)+0.5*'属性输入'!$B$27*(1-C16) -> 19644.359 | E16: =(D16-$D$2)/$D$2 -> 0 | F16: =(D17-D16)/D16 -> 0 | G16: 0.1
A17: 315 | B17: =A17+'属性输入'!$G$25 -> 4715 | C17: =MIN((143*(B17-'属性输入'!$F$11)/(B17-'属性输入'!F$11+10688)+95)/100,1) -> 1 | D17: ='属性输入'!$B$27*C17*(1+('属性输入'!$I$25-'属性输入'!$J$11)*'属性输入'!$P$27)+0.5*'属性输入'!$B$27*(1-C17) -> 19644.359 | E17: =(D17-$D$2)/$D$2 -> 0 | G17: 0.1

Sheet 会心提升收益
A1: 会心提升 | B1: 会心 | C1: 会心率 | D1: 伤害期望计算 | E1: 伤害提升百分比 | F1: 每增加25点会心收益率 | G1: y=0.1 | Q1: 会心提升 | R1: 会心 | S1: 会心率 | T1: 伤害期望计算 | U1: 每增加40点会心收益率
A2: 0 | B2: =A2+'属性输入'!$H$25 -> 4600 | C2: =((115*(B2-'属性输入'!$G$11)-200)/((B2-'属性输入'!$G$11)+2640))/100+'属性输入'!$J$25 -> 0.49525862 | D2: ='属性输入'!$B$27*'属性输入'!$O$27*(1+('属性输入'!$I$25-'属性输入'!$J$11)*C2)+0.5*'属性输入'!$B$27*(1-'属性输入'!$O$27) -> 19672.187 | E2: =(D2-$D$2)/$D$2 -> 0 | F2: =(D3-D2)/D2 -> 0.001798587 | G2: 0.1 | Q2: 0 | R2: =Q2+'属性输入'!$H$25 -> 4600 | S2: =((115*(R2-'属性输入'!$G$11)-200)/((R2-'属性输入'!$G$11)+2666))/100+'属性输入'!$J$25 -> 0.49249893 | T2: ='属性输入'!$B$27*'属性输入'!$O$27*(1+('属性输入'!$I$25-'属性输入'!$J$11)*S2)+0.5*'属性输入'!$B$27*(1-'属性输入'!$O$27) -> 19644.359 | U2: =(T3-T2)/T2 -> 0.0028687494
A3: 25 | B3: =A3+'属性输入'!$H$25 -> 4625 | C3: =((115*(B3-'属性输入'!$G$11)-200)/((B3-'属性输入'!$G$11)+2640))/100+'属性输入'!$J$25 -> 0.49876742 | D3: ='属性输入'!$B$27*'属性输入'!$O$27*(1+('属性输入'!$I$25-'属性输入'!$J$11)*C3)+0.5*'属性输入'!$B$27*(1-'属性输入'!$O$27) -> 19707.569 | E3: =(D3-$D$2)/$D$2 -> 0.001798587 | F3: =(D4-D3)/D3 -> 0.0017762176 | G3: 0.1 | Q3: 40 | R3: =Q3+'属性输入'!$H$25 -> 4640 | S3: =((115*(R3-'属性输入'!$G$11)-200)/((R3-'属性输入'!$G$11)+2666))/100+'属性输入'!$J$25 -> 0.49808755 | T3: ='属性输入'!$B$27*'属性输入'!$O$27*(1+('属性输入'!$I$25-'属性输入'!$J$11)*S3)+0.5*'属性输入'!$B$27*(1-'属性输入'!$O$27) -> 19700.713
A4: 50 | B4: =A4+'属性输入'!$H$25 -> 4650 | C4: =((115*(B4-'属性输入'!$G$11)-200)/((B4-'属性输入'!$G$11)+2640))/100+'属性输入'!$J$25 -> 0.50223881 | D4: ='属性输入'!$B$27*'属性输入'!$O$27*(1+('属性输入'!$I$25-'属性输入'!$J$11)*C4)+0.5*'属性输入'!$B$27*(1-'属性输入'!$O$27) -> 19742.574 | E4: =(D4-$D$2)/$D$2 -> 0.0035779993 | F4: =(D5-D4)/D4 -> 0.0017542658 | G4: 0.1 | Q4: 137 | R4: =Q4+'属性输入'!$H$25 -> 4737 | S4: =((115*(R4-'属性输入'!$G$11)-200)/((R4-'属性输入'!$G$11)+2666))/100+'属性输入'!$J$25 -> 0.51125338 | T4: ='属性输入'!$B$27*'属性输入'!$O$27*(1+('属性输入'!$I$25-'属性输入'!$J$11)*S4)+0.5*'属性输入'!$B$27*(1-'属性输入'!$O$27) -> 19833.476 | V4: =(T4-T2)/T2 -> 0.0096270345
A5: 75 | B5: =A5+'属性输入'!$H$25 -> 4675 | C5: =((115*(B5-'属性输入'!$G$11)-200)/((B5-'属性输入'!$G$11)+2640))/100+'属性输入'!$J$25 -> 0.50567338 | D5: ='属性输入'!$B$27*'属性输入'!$O$27*(1+('属性输入'!$I$25-'属性输入'!$J$11)*C5)+0.5*'属性输入'!$B$27*(1-'属性输入'!$O$27) -> 19777.208 | E5: =(D5-$D$2)/$D$2 -> 0.0053385418 | F5: =(D6-D5)/D5 -> 0.0017327213 | G5: 0.1 | Q5: 100 | R5: =Q5+'属性输入'!$H$25 -> 4700 | S5: =((115*(R5-'属性输入'!$G$11)-200)/((R5-'属性输入'!$G$11)+2666))/100+'属性输入'!$J$25 -> 0.50629459 | T5: ='属性输入'!$B$27*'属性输入'!$O$27*(1+('属性输入'!$I$25-'属性输入'!$J$11)*S5)+0.5*'属性输入'!$B$27*(1-'属性输入'!$O$27) -> 19783.472 | U5: =(T5-T2)/T2 -> 0.0070815856
A6: 100 | B6: =A6+'属性输入'!$H$25 -> 4700 | C6: =((115*(B6-'属性输入'!$G$11)-200)/((B6-'属性输入'!$G$11)+2640))/100+'属性输入'!$J$25 -> 0.50907173 | D6: ='属性输入'!$B$27*'属性输入'!$O$27*(1+('属性输入'!$I$25-'属性输入'!$J$11)*C6)+0.5*'属性输入'!$B$27*(1-'属性输入'!$O$27) -> 19811.476 | E6: =(D6-$D$2)/$D$2 -> 0.0070805133 | F6: =(D7-D6)/D6 -> 0.0017115738 | G6: 0.1
A7: 125 | B7: =A7+'属性输入'!$H$25 -> 4725 | C7: =((115*(B7-'属性输入'!$G$11)-200)/((B7-'属性输入'!$G$11)+2640))/100+'属性输入'!$J$25 -> 0.51243442 | D7: ='属性输入'!$B$27*'属性输入'!$O$27*(1+('属性输入'!$I$25-'属性输入'!$J$11)*C7)+0.5*'属性输入'!$B$27*(1-'属性输入'!$O$27) -> 19845.385 | E7: =(D7-$D$2)/$D$2 -> 0.0088042059 | F7: =(D8-D7)/D7 -> 0.0016908138 | G7: 0.1
A8: 150 | B8: =A8+'属性输入'!$H$25 -> 4750 | C8: =((115*(B8-'属性输入'!$G$11)-200)/((B8-'属性输入'!$G$11)+2640))/100+'属性输入'!$J$25 -> 0.515762 | D8: ='属性输入'!$B$27*'属性输入'!$O$27*(1+('属性输入'!$I$25-'属性输入'!$J$11)*C8)+0.5*'属性输入'!$B$27*(1-'属性输入'!$O$27) -> 19878.94 | E8: =(D8-$D$2)/$D$2 -> 0.010509906 | F8: =(D9-D8)/D8 -> 0.0016704316 | G8: 0.1
A9: 175 | B9: =A9+'属性输入'!$H$25 -> 4775 | C9: =((115*(B9-'属性输入'!$G$11)-200)/((B9-'属性输入'!$G$11)+2640))/100+'属性输入'!$J$25 -> 0.51905504 | D9: ='属性输入'!$B$27*'属性输入'!$O$27*(1+('属性输入'!$I$25-'属性输入'!$J$11)*C9)+0.5*'属性输入'!$B$27*(1-'属性输入'!$O$27) -> 19912.146 | E9: =(D9-$D$2)/$D$2 -> 0.012197894 | F9: =(D10-D9)/D9 -> 0.0016504182 | G9: 0.1
A10: 200 | B10: =A10+'属性输入'!$H$25 -> 4800 | C10: =((115*(B10-'属性输入'!$G$11)-200)/((B10-'属性输入'!$G$11)+2640))/100+'属性输入'!$J$25 -> 0.52231405 | D10: ='属性输入'!$B$27*'属性输入'!$O$27*(1+('属性输入'!$I$25-'属性输入'!$J$11)*C10)+0.5*'属性输入'!$B$27*(1-'属性输入'!$O$27) -> 19945.01 | E10: =(D10-$D$2)/$D$2 -> 0.013868443 | F10: =(D11-D10)/D10 -> 0.0016307645 | G10: 0.1
A11: 225 | B11: =A11+'属性输入'!$H$25 -> 4825 | C11: =((115*(B11-'属性输入'!$G$11)-200)/((B11-'属性输入'!$G$11)+2640))/100+'属性输入'!$J$25 -> 0.52553957 | D11: ='属性输入'!$B$27*'属性输入'!$O$27*(1+('属性输入'!$I$25-'属性输入'!$J$11)*C11)+0.5*'属性输入'!$B$27*(1-'属性输入'!$O$27) -> 19977.535 | E11: =(D11-$D$2)/$D$2 -> 0.015521824 | F11: =(D12-D11)/D11 -> 0.0016114621 | G11: 0.1
A12: 250 | B12: =A12+'属性输入'!$H$25 -> 4850 | C12: =((115*(B12-'属性输入'!$G$11)-200)/((B12-'属性输入'!$G$11)+2640))/100+'属性输入'!$J$25 -> 0.52873211 | D12: ='属性输入'!$B$27*'属性输入'!$O$27*(1+('属性输入'!$I$25-'属性输入'!$J$11)*C12)+0.5*'属性输入'!$B$27*(1-'属性输入'!$O$27) -> 20009.728 | E12: =(D12-$D$2)/$D$2 -> 0.017158299 | F12: =(D13-D12)/D12 -> 0.0015925026 | G12: 0.1
A13: 275 | B13: =A13+'属性输入'!$H$25 -> 4875 | C13: =((115*(B13-'属性输入'!$G$11)-200)/((B13-'属性输入'!$G$11)+2640))/100+'属性输入'!$J$25 -> 0.53189217 | D13: ='属性输入'!$B$27*'属性输入'!$O$27*(1+('属性输入'!$I$25-'属性输入'!$J$11)*C13)+0.5*'属性输入'!$B$27*(1-'属性输入'!$O$27) -> 20041.594 | E13: =(D13-$D$2)/$D$2 -> 0.018778126 | F13: =(D14-D13)/D13 -> 0.0015738777 | G13: 0.1
A14: 300 | B14: =A14+'属性输入'!$H$25 -> 4900 | C14: =((115*(B14-'属性输入'!$G$11)-200)/((B14-'属性输入'!$G$11)+2640))/100+'属性输入'!$J$25 -> 0.53502024 | D14: ='属性输入'!$B$27*'属性输入'!$O$27*(1+('属性输入'!$I$25-'属性输入'!$J$11)*C14)+0.5*'属性输入'!$B$27*(1-'属性输入'!$O$27) -> 20073.137 | E14: =(D14-$D$2)/$D$2 -> 0.020381559 | F14: =(D15-D14)/D14 -> 0.0015555797 | G14: 0.1
A15: 325 | B15: =A15+'属性输入'!$H$25 -> 4925 | C15: =((115*(B15-'属性输入'!$G$11)-200)/((B15-'属性输入'!$G$11)+2640))/100+'属性输入'!$J$25 -> 0.53811682 | D15: ='属性输入'!$B$27*'属性输入'!$O$27*(1+('属性输入'!$I$25-'属性输入'!$J$11)*C15)+0.5*'属性输入'!$B$27*(1-'属性输入'!$O$27) -> 20104.362 | E15: =(D15-$D$2)/$D$2 -> 0.021968843 | F15: =(D16-D15)/D15 -> 0.0015376009 | G15: 0.1
A16: 350 | B16: =A16+'属性输入'!$H$25 -> 4950 | C16: =((115*(B16-'属性输入'!$G$11)-200)/((B16-'属性输入'!$G$11)+2640))/100+'属性输入'!$J$25 -> 0.54118236 | D16: ='属性输入'!$B$27*'属性输入'!$O$27*(1+('属性输入'!$I$25-'属性输入'!$J$11)*C16)+0.5*'属性输入'!$B$27*(1-'属性输入'!$O$27) -> 20135.275 | E16: =(D16-$D$2)/$D$2 -> 0.023540224 | F16: =(D17-D16)/D16 -> 0.0015199338 | G16: 0.1
A17: 375 | B17: =A17+'属性输入'!$H$25 -> 4975 | C17: =((115*(B17-'属性输入'!$G$11)-200)/((B17-'属性输入'!$G$11)+2640))/100+'属性输入'!$J$25 -> 0.54421735 | D17: ='属性输入'!$B$27*'属性输入'!$O$27*(1+('属性输入'!$I$25-'属性输入'!$J$11)*C17)+0.5*'属性输入'!$B$27*(1-'属性输入'!$O$27) -> 20165.879 | E17: =(D17-$D$2)/$D$2 -> 0.025095937 | F17: =(D18-D17)/D17 -> 0.0015025713 | G17: 0.1
... A20: 450 | B20: =A20+'属性输入'!$H$25 -> 5050 | C20: =((115*(B20-'属性输入'!$G$11)-200)/((B20-'属性输入'!$G$11)+2640))/100+'属性输入'!$J$25 -> 0.55314342 | D20: ='属性输入'!$B$27*'属性输入'!$O$27*(1+('属性输入'!$I$25-'属性输入'!$J$11)*C20)+0.5*'属性输入'!$B$27*(1-'属性输入'!$O$27) -> 20255.888 | E20: =(D20-$D$2)/$D$2 -> 0.029671385 | F20: =(D21-D20)/D20 -> 0.0014522421 | G20: 0.1
A21: 475 | B21: =A21+'属性输入'!$H$25 -> 5075 | C21: =((115*(B21-'属性输入'!$G$11)-200)/((B21-'属性输入'!$G$11)+2640))/100+'属性输入'!$J$25 -> 0.55606061 | D21: ='属性输入'!$B$27*'属性输入'!$O$27*(1+('属性输入'!$I$25-'属性输入'!$J$11)*C21)+0.5*'属性输入'!$B$27*(1-'属性输入'!$O$27) -> 20285.304 | E21: =(D21-$D$2)/$D$2 -> 0.031166717 | G21: 0.1
